Workbook

Sheet 📌 NAVIGATION
A1: 🚀 MiDAY System Navigation
A3: 🏠 DASHBOARD | B3: Complete business overview with charts & KPIs
A4: 📋 PRODUCTS | B4: Master product list (add/remove products here)
A5: 📊 SALES | B5: All sales in one place
A6: 👤 CUSTOMERS | B6: Customer tracking and history
A7: 📦 INVENTORY | B7: Raw materials + Finished goods (with payables)
A8: 💰 EXPENSES | B8: Fixed, Variable, Operating expenses
A9: 👥 FOUNDERS | B9: Capital contributions tracking
A10: 🔧 ASSETS | B10: Equipment and machinery
A11: 📊 WEEKLY PERFORMANCE | B11: Week-by-week tracking
A12: 📈 MONTHLY PERFORMANCE | B12: Monthly trends and targets
A13: 📊 COGS | B13: Cost of Goods Sold lookup
A14: MASTER_SALES | B14: Consolidated sales data
... A17: 👥 PROFIT SHARING | B17: Founder profit distribution

Sheet 🏠 DASHBOARD
A2: 📅 Last Updated: | B2: =TODAY() -> 46257
A4: 📊 Quick Stats
A5: 📈 Revenue (MTD) | C5: 💰 Net Profit (MTD) | E5: 📦 Inventory Value | G5: 👥 Total Capital | I5: 📊 Revenue (Today)
A6: =SUMIFS(MASTER_SALES!G:G, MASTER_SALES!A:A, ">="&EOMONTH(TODAY(),-1)+1) -> 735000 | C6: =SUMIFS(MASTER_SALES!G:G, MASTER_SALES!A:A, ">="&EOMONTH(TODAY(),-1)+1)-SUMIFS(MASTER_SALES!N:N, MASTER_SALES!A:A, ">="&EOMONTH(TODAY(),-1)+1)-SUMIFS('💰 EXPENSES'!F:F, '💰 EXPENSES'!A:A, ">="&EOMONTH(TODAY(),-1)+1) -> -478930 | E6: =SUM('📦 INVENTORY'!G:G) -> 4861529.8 | G6: =SUM('👥 FOUNDERS'!E:E, '👥 FOUNDERS'!F:F, '👥 FOUNDERS'!G:G, '👥 FOUNDERS'!H:H) -> 966000 | I6: =SUMIFS(MASTER_SALES!G:G, MASTER_SALES!A:A, "="&TODAY()) -> 0
A8: 📊 RECEIVABLES & PAYABLES SUMMARY
A9: Metric | B9: Amount (UGX) | C9: Status | D9: Action Required
A10: 💰 Total Receivables | B10: =SUMIFS('📊 SALES'!G:G, '📊 SALES'!H:H, "Pending") + SUMIFS('📊 SALES'!G:G, '📊 SALES'!H:H, "Partial") + SUMIFS('📊 SALES'!G:G, '📊 SALES'!H:H, "Credit") -> 139000 | C10: =IF(B10>0, "⚠️ Follow up", "✅ All Paid") -> ⚠️ Follow up | D10: =IF(B10>0, "Contact customers", "No action needed") -> Contact customers
A11: 💳 Payables (Expenses) | B11: =SUMIFS('💰 EXPENSES'!F:F, '💰 EXPENSES'!H:H, "Pending") + SUMIFS('💰 EXPENSES'!F:F, '💰 EXPENSES'!H:H, "Overdue") -> 0
A12: 📦 Payables (Inventory) | B12: =SUMIFS('📦 INVENTORY'!G:G, '📦 INVENTORY'!L:L, "Pending") + SUMIFS('📦 INVENTORY'!G:G, '📦 INVENTORY'!L:L, "Overdue") -> 0
A13: 💳 TOTAL PAYABLES | B13: =B11+B12 -> 0 | C13: =IF(B13>0, "⚠️ Pay soon", "✅ No Payables") -> ✅ No Payables | D13: =IF(B13>0, "Schedule payments", "No action needed") -> No action needed
A14: 📊 Net Position | B14: =B10-B13 -> 139000 | C14: =IF(B14>0, "✅ Healthy", IF(B14<0, "🔴 Review urgently", "✅ Balanced")) -> ✅ Healthy | D14: =IF(B14<0, "Collect receivables faster", "On track") -> On track

Sheet 📋 PRODUCTS
A1: Product ID | B1: Product Name | C1: Category | D1: Unit Price (UGX) | E1: Active | F1: Notes
A2: P001 | B2: Kavera 15g | C2: Kavera | D2: 500 | E2: FALSE | F2: Core product
A3: P002 | B3: Kavera 25g | C3: Kavera | D3: 1000 | E3: FALSE | F3: Core product
A4: P003 | B4: Kavera 40g | C4: Kavera | D4: 1000 | E4: FALSE | F4: Core product
A5: P004 | B5: Baby Tin 18g | C5: Baby Tin | D5: 2000 | E5: TRUE | F5: Core product
A6: P005 | B6: Baby Tin 20g | C6: Baby Tin | D6: 2000 | E6: FALSE | F6: Core product
A7: P006 | B7: Spiced 50g | C7: Spiced | D7: 5000 | E7: TRUE | F7: Core product
A8: P007 | B8: Black Pack 100g | C8: Black Pack Small | D8: 10000 | E8: TRUE | F8: Core product
A9: P008 | B9: MiDAY Combo | C9: Combo | D9: 12000 | E9: TRUE | F9: Core product
A10: P009 | B10: Quail Eggs 18s | C10: Eggs | D10: 8000 | E10: TRUE | F10: Core product
A11: P010 | B11: Roasted Coffee Beans (Kg) | C11: Roasted Bean | D11: 60000 | E11: TRUE | F11: Core product
A12: P011 | B12: Medium Roast Fine Grind (250g) | C12: Black Pack Medium | D12: 25000 | E12: TRUE | F12: Core product
A13: P012 | B13: Medium Roast Medium Grind (250g) | C13: Black Pack Medium | D13: 25000 | E13: TRUE | F13: Core product
... A23: P022 | B23: Dark Roast Medium Grind (kg) | C23: Black Pack Large | D23: 60000 | E23: TRUE | F23: Core product
A24: P023
A25: P024

Sheet 👤 CUSTOMERS
A1: Customer ID | B1: Customer Name | C1: Contact | D1: Location | E1: Total Purchases | F1: Last Purchase | G1: Total Spend (UGX) | H1: Status

Sheet 📦 INVENTORY
A1: Date | B1: Item Category | C1: Item Name | D1: Supplier | E1: Quantity Received | F1: Unit Cost (UGX) | G1: Total Cost (UGX) | H1: Quantity Used | I1: Remaining Stock | J1: Reorder Level | K1: Status | L1: Payment Status | M1: Notes
A2: 46181 | B2: Raw Material | C2: Arabica and robaster | D2: UGACOF | E2: 10 | F2: 15000 | G2: =E2*F2 -> 150000 | H2: 10 | I2: =E2-H2 -> 0 | K2: Out of Stock | L2: Paid
A3: 46181 | B3: Raw Material | C3: Black packs 100g | D3: Bugolobi | E3: 50 | F3: 1200 | G3: =E3*F3 -> 60000 | H3: 18 | I3: =E3-H3 -> 32 | K3: In Stock | L3: Paid
A4: 46181 | B4: Raw Material | C4: Polythene 1.5inch | D4: Kireka | E4: 1 | F4: 3000 | G4: =E4*F4 -> 3000 | H4: 1 | I4: =E4-H4 -> 0 | K4: Out of Stock | L4: Paid
A5: 46181 | B5: Raw Material | C5: Polythene 2.5inch | D5: Kireka | E5: 1 | F5: 3000 | G5: =E5*F5 -> 3000 | H5: 1 | I5: =E5-H5 -> 0 | K5: Out of Stock | L5: Paid
A6: 46181 | B6: Raw Material | C6: Polythene 3inch | D6: Kireka | E6: 1 | F6: 3000 | G6: =E6*F6 -> 3000 | H6: 1 | I6: =E6-H6 -> 0 | K6: Out of Stock | L6: Paid
A7: 46182 | B7: Raw Material | C7: Baby tins | D7: Town | E7: 230 | F7: 369.565 | G7: =E7*F7 -> 84999.95 | H7: 18 | I7: =E7-H7 -> 212 | K7: In Stock | L7: Paid
A8: 46184 | B8: Finished Good | C8: Baby tins 20g | D8: Kasokoso | E8: 18 | F8: 2000 | G8: =E8*F8 -> 36000 | H8: 18 | I8: =E8-H8 -> 0 | K8: Out of Stock | L8: Paid
A9: 46184 | B9: Finished Good | C9: Kavera 15g | D9: Kasokoso | E9: 15 | F9: 500 | G9: =E9*F9 -> 7500 | H9: 15 | I9: =E9-H9 -> 0 | K9: Out of Stock | L9: Paid
A10: 46184 | B10: Finished Good | C10: Kavera 40g | D10: Kasokoso | E10: 126 | F10: 1000 | G10: =E10*F10 -> 126000 | H10: 126 | I10: =E10-H10 -> 0 | K10: Out of Stock | L10: Paid
A11: 46184 | B11: Finished Good | C11: Black packs 100g | D11: Kasokoso | E11: 18 | F11: 10000 | G11: =E11*F11 -> 180000 | H11: 18 | I11: =E11-H11 -> 0 | K11: Out of Stock | L11: Paid
A12: 46205 | B12: Raw Material | C12: Arabica and robaster | D12: UGACOF | E12: 10 | F12: 22000 | G12: =E12*F12 -> 220000 | H12: 10 | I12: =E12-H12 -> 0 | K12: Out of Stock | L12: Paid
A13: 46207 | B13: Finished Good | C13: Baby tin 18g | D13: Kasokoso | E13: 167 | F13: 2000 | G13: =E13*F13 -> 334000 | H13: 167 | I13: =E13-H13 -> 0 | K13: Out of Stock | L13: Paid
A14: 46207 | B14: Finished Good | C14: Black pack 100g | D14: Kasokoso | E14: 1 | F14: 10000 | G14: =E14*F14 -> 10000 | H14: 1 | I14: 31 | K14: In Stock | L14: Paid | M14: Deducted from last batch on June 6th
A15: 46207 | B15: Finished Good | C15: Kavera 25g | D15: Kasokoso | E15: 160 | F15: 1000 | G15: =E15*F15 -> 160000 | H15: 160 | I15: =E15-H15 -> 0 | K15: Out of Stock | L15: Paid
A16: 46233 | B16: Raw Material | C16: Arabica and robaster | E16: 66 | F16: 10909.09 | G16: =E16*F16 -> 719999.94 | H16: 60 | K16: In Stock | L16: Paid
A17: 46233 | B17: Raw Material | C17: Gold tins 50g | D17: Town | E17: 107 | F17: 1290 | G17: =E17*F17 -> 138030 | I17: =E17-H17 -> 107 | K17: In Stock
A18: 46233 | B18: Raw Material | C18: Baby tins | D18: Town | E18: 230 | F18: 369.565 | G18: =E18*F18 -> 84999.95 | H18: 230 | I18: =E18-H18 -> 0 | K18: In Stock
A19: 46233 | B19: Raw Material | C19: Coffee spices | D19: Town | E19: 1 | F19: 5000 | G19: =E19*F19 -> 5000 | H19: 1 | I19: =E19-H19 -> 0 | K19: Out of Stock
A20: 46233 | B20: Raw Material | C20: Coffee premium | E20: 5 | F20: 25000 | G20: =E20*F20 -> 125000 | I20: =E20-H20 -> 5
A21: 46235 | B21: Finished Good | C21: Black pack 100g | E21: 15 | F21: 10000 | G21: =E21*F21 -> 150000 | H21: 15 | I21: 0 | K21: Low Stock | M21: Deducted from June 6th balance 16packs
A22: 46236 | B22: Finished Good | C22: Masala 50g | E22: 106 | F22: 5000 | G22: =E22*F22 -> 530000 | H22: 103 | I22: =E22-H22 -> 3 | K22: Low Stock
A23: 46236 | B23: Finished Good | C23: Baby tins 18g | E23: 230 | F23: 2000 | G23: =E23*F23 -> 460000 | I23: =E23-H23 -> 230
A24: 46237 | B24: Finished Good | C24: Black pack 1kg special order | E24: 1 | F24: 60000 | G24: =E24*F24 -> 60000 | I24: =E24-H24 -> 1
A25: 46239 | B25: Raw Material | C25: Roasted coffee | E25: 3 | F25: 10000 | G25: =E25*F25 -> 30000 | I25: =E25-H25 -> 3
A26: 46239 | B26: Raw Material | C26: Black packs 250g | E26: 3 | F26: 2000 | G26: =E26*F26 -> 6000 | I26: =E26-H26 -> 3
A27: 46240 | B27: Finished Good | C27: Dark roast fine grind 250g | E27: 1 | F27: 25000 | G27: =E27*F27 -> 25000 | H27: 1 | I27: =E27-H27 -> 0
A28: 46240 | B28: Finished Good | C28: Dark roast medium grind 250g | E28: 1 | F28: 25000 | G28: =E28*F28 -> 25000 | H28: 1 | I28: =E28-H28 -> 0
A29: 46240 | B29: Finished Good | C29: Medium roast medium grind 250g | E29: 1 | F29: 25000 | G29: =E29*F29 -> 25000 | H29: 1 | I29: =E29-H29 -> 0
A30: 46251 | B30: Raw Material | C30: Gold tins 50g | E30: 100 | F30: 1450 | G30: =E30*F30 -> 145000 | I30: =E30-H30 -> 100
A31: 46251 | B31: Raw Material | C31: Black pack 100g | E31: 50 | F31: 1200 | G31: =E31*F31 -> 60000 | I31: =E31-H31 -> 50
A32: 46251 | B32: Raw Material | C32: Baby tin | E32: 230 | F32: 369.565 | G32: =E32*F32 -> 84999.95 | H32: 130 | I32: =E32-H32 -> 100
A33: 46251 | B33: Raw Material | C33: Spices | E33: 10 | F33: 5000 | G33: =E33*F33 -> 50000 | I33: =E33-H33 -> 10
A34: 46251 | B34: Finished Good | C34: Baby tins | E34: 130 | F34: 2000 | G34: =E34*F34 -> 260000 | I34: =E34-H34 -> 130
A35: 46251 | B35: Finished Good | C35: Masala 50g | E35: 100 | F35: 5000 | G35: =E35*F35 -> 500000 | I35: =E35-H35 -> 100
G36: =E36*F36 -> 0 | I36: =E36-H36 -> 0
G37: =E37*F37 -> 0 | I37: =E37-H37 -> 0
G38: =E38*F38 -> 0 | I38: =E38-H38 -> 0
G39: =E39*F39 -> 0 | I39: =E39-H39 -> 0
G40: =E40*F40 -> 0 | I40: =E40-H40 -> 0
...

Sheet 💰 EXPENSES
A1: Date | B1: Expense Type | C1: Category | D1: Description | E1: Supplier/Vendor | F1: Amount (UGX) | G1: Payment Method | H1: Status | I1: Notes
A2: 46182 | B2: Variable | C2: Other | D2: Roasting | F2: 25000 | G2: Cash | H2: Paid
A3: 46182 | B3: Variable | C3: Other | D3: Grinding | F3: 5000 | G3: Cash | H3: Paid
A4: 46182 | B4: Operating | C4: Packaging | D4: Stickers | F4: 6000 | G4: Cash | H4: Paid
A5: 46183 | B5: Operating | C5: Transport & Fuel | D5: Coffee and stickers | F5: 45000 | G5: Cash | H5: Paid
A6: 46184 | B6: Operating | C6: Salaries | D6: Field marketing | F6: 55000 | G6: Cash | H6: Paid
A7: 46205 | B7: Operating | C7: Packaging | D7: Stickers | F7: 37000 | G7: Cash | H7: Paid
A8: 46207 | B8: Operating | C8: Salaries | D8: Field marketing | F8: 45000 | G8: Cash | H8: Paid
A9: 46207 | B9: Operating | C9: Transport & Fuel | D9: Stickers | F9: 8000 | G9: Cash | H9: Paid
A10: 46207 | B10: Variable | C10: Other | D10: Roasting | F10: 25000 | G10: Cash | H10: Paid
A11: 46207 | B11: Variable | C11: Other | D11: Grinding | F11: 5000 | G11: Cash | H11: Paid
A12: 46233 | B12: Operating | C12: Packaging | D12: Stickers | F12: 90000 | G12: Cash | H12: Paid
A13: 46233 | B13: Operating | C13: Transport & Fuel | D13: Stickers | F13: 21000 | G13: Cash | H13: Paid
... A22: 46233 | B22: Operating | C22: Packaging | D22: Stickers | F22: 25000 | G22: Cash | H22: Paid
A23: 46233 | B23: Operating | C23: Transport & Fuel | F23: 34000 | G23: Cash | H23: Paid
A24: 46233 | B24: Operating | C24: Transport & Fuel | D24: Coffee premium | F24: 13000 | G24: Cash | H24: Paid
A25: 46235 | B25: Operating | C25: Transport & Fuel | D25: Precious and Irene | F25: 8000 | G25: Cash | H25: Paid
A26: 46235 | B26: Operating | C26: Other | D26: Welfare | F26: 12000 | G26: Cash | H26: Paid
A27: 46235 | B27: Fixed | C27: Rent | D27: Mbalwa - 4months | F27: 400000 | G27: Cash | H27: Paid
A28: 46235 | B28: Operating | C28: Transport & Fuel | D28: Field marketing | F28: 15000 | G28: Cash | H28: Paid
A29: 46235 | B29: Operating | C29: Transport & Fuel | D29: Field marketing | F29: 4000 | G29: Cash | H29: Paid
A30: 46235 | B30: Operating | C30: Equipment | D30: Gloves | F30: 25000 | G30: Cash | H30: Paid
A31: 46237 | B31: Operating | C31: Packaging | D31: Sticker for Parteker's coffee | F31: 4000 | G31: Cash | H31: Paid
A32: 46237 | B32: Operating | C32: Transport & Fuel | D32: Parteker's coffee | F32: 9000 | G32: Cash | H32: Paid
A33: 46237 | B33: Operating | C33: Packaging | D33: stickers | F33: 1000 | G33: Cash | H33: Paid
A34: 46240 | B34: Operating | C34: Transport & Fuel | D34: Field marketing | F34: 10000 | G34: Cash | H34: Paid
A35: 46240 | B35: Operating | C35: Equipment | D35: Black bag | F35: 1000 | G35: Cash | H35: Paid
... A40: 46243 | B40: Operating | C40: Transport & Fuel | D40: Mushabe | F40: 4000 | G40: Cash | H40: Paid
A41: 46243 | B41: Operating | C41: Transport & Fuel | D41: Field marketing | F41: 22000 | G41: Cash | H41: Paid | I41: 4th August expense
A42: 46243 | B42: Operating | C42: Other | D42: Welfare | F42: 8500 | G42: Cash | H42: Paid
A43: 46244 | B43: Operating | C43: Transport & Fuel | D43: Field marketing | F43: 4000 | G43: Cash | H43: Paid
A44: 46244 | B44: Operating | C44: Other | D44: Welfare | F44: 6000 | G44: Cash | H44: Paid
A45: 46244 | B45: Operating | C45: Transport & Fuel | D45: Mushabe | F45: 20000 | G45: Cash | H45: Paid
A46: 46245 | B46: Operating | C46: Transport & Fuel | D46: Field marketing | F46: 10000 | G46: Cash | H46: Paid
A47: 46245 | B47: Operating | C47: Other | D47: Welfare for 2 agents | F47: 10000 | G47: Cash | H47: Paid
A48: 46246 | B48: Operating | C48: Other | D48: Welfare for 3agents | F48: 12000 | G48: Cash | H48: Paid
A49: 46246 | B49: Operating | C49: Transport & Fuel | D49: Field marketing | F49: 20000 | G49: Cash | H49: Paid
A50: 46246 | B50: Operating | C50: Other | D50: Lost cash in the field | F50: 10000 | G50: Cash | H50: Paid
A51: 46247 | B51: Operating | C51: Other | D51: Meals | F51: 6500 | G51: Cash | H51: Paid
A52: 46247 | B52: Operating | C52: Other | D52: TIN URA | F52: 40000 | G52: Cash | H52: Paid
...

Sheet 👥 FOUNDERS
A1: Date | B1: Contribution Type | C1: Notes | D1: Transaction ID | E1: SY (UGX) | F1: Tendo (UGX) | G1: Antipas (UGX) | H1: Ashaba (UGX) | I1: TOTAL (UGX)
A2: 46245 | B2: Additional Investment | H2: 256000 | I2: =SUM(E2,F2,G2,H2) -> 256000
A3: 46247 | B3: Additional Investment | H3: 60000 | I3: =SUM(E3,F3,G3,H3) -> 60000
A4: 46250 | B4: Additional Investment | F4: 600000 | I4: =SUM(E4,F4,G4,H4) -> 600000
A5: 46250 | B5: Additional Investment | H5: 50000 | I5: =SUM(E5,F5,G5,H5) -> 50000
I6: =SUM(E6,F6,G6,H6) -> 0
I7: =SUM(E7,F7,G7,H7) -> 0
I8: =SUM(E8,F8,G8,H8) -> 0
I9: =SUM(E9,F9,G9,H9) -> 0
I10: =SUM(E10,F10,G10,H10) -> 0
I11: =SUM(E11,F11,G11,H11) -> 0
I12: =SUM(E12,F12,G12,H12) -> 0
I13: =SUM(E13,F13,G13,H13) -> 0
I14: =SUM(E14,F14,G14,H14) -> 0
I15: =SUM(E15,F15,G15,H15) -> 0
I16: =SUM(E16,F16,G16,H16) -> 0
I17: =SUM(E17,F17,G17,H17) -> 0
... I501: =SUM(E501,F501,G501,H501) -> 0

Sheet 📊 SALES
A1: Date | B1: Product ID | C1: Product Name | D1: Category | E1: Quantity | F1: Unit Price | G1: Revenue | H1: Payment Status | I1: Agent | J1: Customer | K1: Customer ID | L1: Payment Method | M1: Notes
A2: 46184 | B2: P003 | C2: =IFERROR(VLOOKUP(B2, '📋 PRODUCTS'!A:D, 2, FALSE), "") -> Kavera 40g | D2: =IFERROR(VLOOKUP(B2, '📋 PRODUCTS'!A:D, 3, FALSE), "") -> Kavera | E2: 126 | F2: =IFERROR(VLOOKUP(B2, '📋 PRODUCTS'!A:D, 4, FALSE), "") -> 1000 | G2: =E2*F2 -> 126000 | H2: Paid | L2: Cash
A3: 46184 | B3: P004 | C3: =IFERROR(VLOOKUP(B3, '📋 PRODUCTS'!A:D, 2, FALSE), "") -> Baby Tin 18g | D3: =IFERROR(VLOOKUP(B3, '📋 PRODUCTS'!A:D, 3, FALSE), "") -> Baby Tin | E3: 18 | F3: =IFERROR(VLOOKUP(B3, '📋 PRODUCTS'!A:D, 4, FALSE), "") -> 2000 | G3: =E3*F3 -> 36000 | H3: Paid | L3: Cash
A4: 46185 | B4: P007 | C4: =IFERROR(VLOOKUP(B4, '📋 PRODUCTS'!A:D, 2, FALSE), "") -> Black Pack 100g | D4: =IFERROR(VLOOKUP(B4, '📋 PRODUCTS'!A:D, 3, FALSE), "") -> Black Pack Small | E4: 18 | F4: =IFERROR(VLOOKUP(B4, '📋 PRODUCTS'!A:D, 4, FALSE), "") -> 10000 | G4: =E4*F4 -> 180000 | H4: Paid | L4: Cash
A5: 46185 | B5: P001 | C5: =IFERROR(VLOOKUP(B5, '📋 PRODUCTS'!A:D, 2, FALSE), "") -> Kavera 15g | D5: =IFERROR(VLOOKUP(B5, '📋 PRODUCTS'!A:D, 3, FALSE), "") -> Kavera | E5: 15 | F5: =IFERROR(VLOOKUP(B5, '📋 PRODUCTS'!A:D, 4, FALSE), "") -> 500 | G5: =E5*F5 -> 7500 | H5: Paid | L5: Cash
A6: 46185 | B6: P007 | C6: =IFERROR(VLOOKUP(B6, '📋 PRODUCTS'!A:D, 2, FALSE), "") -> Black Pack 100g | D6: =IFERROR(VLOOKUP(B6, '📋 PRODUCTS'!A:D, 3, FALSE), "") -> Black Pack Small | E6: 6 | F6: =IFERROR(VLOOKUP(B6, '📋 PRODUCTS'!A:D, 4, FALSE), "") -> 10000 | G6: =E6*F6 -> 60000 | H6: Paid | L6: Cash
A7: 46205 | B7: P002 | C7: =IFERROR(VLOOKUP(B7, '📋 PRODUCTS'!A:D, 2, FALSE), "") -> Kavera 25g | D7: =IFERROR(VLOOKUP(B7, '📋 PRODUCTS'!A:D, 3, FALSE), "") -> Kavera | E7: 160 | F7: =IFERROR(VLOOKUP(B7, '📋 PRODUCTS'!A:D, 4, FALSE), "") -> 1000 | G7: =E7*F7 -> 160000 | H7: Paid | L7: Cash
A8: 46207 | B8: P007 | C8: =IFERROR(VLOOKUP(B8, '📋 PRODUCTS'!A:D, 2, FALSE), "") -> Black Pack 100g | D8: =IFERROR(VLOOKUP(B8, '📋 PRODUCTS'!A:D, 3, FALSE), "") -> Black Pack Small | E8: 1 | F8: =IFERROR(VLOOKUP(B8, '📋 PRODUCTS'!A:D, 4, FALSE), "") -> 10000 | G8: =E8*F8 -> 10000 | H8: Paid | L8: Cash
A9: 46207 | B9: P004 | C9: =IFERROR(VLOOKUP(B9, '📋 PRODUCTS'!A:D, 2, FALSE), "") -> Baby Tin 18g | D9: =IFERROR(VLOOKUP(B9, '📋 PRODUCTS'!A:D, 3, FALSE), "") -> Baby Tin | E9: 167 | F9: =IFERROR(VLOOKUP(B9, '📋 PRODUCTS'!A:D, 4, FALSE), "") -> 2000 | G9: =E9*F9 -> 334000 | H9: Paid | L9: Cash
A10: 46235 | B10: P009 | C10: =IFERROR(VLOOKUP(B10, '📋 PRODUCTS'!A:D, 2, FALSE), "") -> Quail Eggs 18s | D10: =IFERROR(VLOOKUP(B10, '📋 PRODUCTS'!A:D, 3, FALSE), "") -> Eggs | E10: 8 | F10: =IFERROR(VLOOKUP(B10, '📋 PRODUCTS'!A:D, 4, FALSE), "") -> 8000 | G10: =E10*F10 -> 64000 | H10: Partial | L10: Cash | M10: 2trays in debt
A11: 46235 | B11: P006 | C11: =IFERROR(VLOOKUP(B11, '📋 PRODUCTS'!A:D, 2, FALSE), "") -> Spiced 50g | D11: =IFERROR(VLOOKUP(B11, '📋 PRODUCTS'!A:D, 3, FALSE), "") -> Spiced | E11: 8 | F11: =IFERROR(VLOOKUP(B11, '📋 PRODUCTS'!A:D, 4, FALSE), "") -> 5000 | G11: =E11*F11 -> 40000 | H11: Paid | L11: Cash
A12: 46235 | B12: P007 | C12: =IFERROR(VLOOKUP(B12, '📋 PRODUCTS'!A:D, 2, FALSE), "") -> Black Pack 100g | D12: =IFERROR(VLOOKUP(B12, '📋 PRODUCTS'!A:D, 3, FALSE), "") -> Black Pack Small | E12: 6 | F12: =IFERROR(VLOOKUP(B12, '📋 PRODUCTS'!A:D, 4, FALSE), "") -> 10000 | G12: =E12*F12 -> 60000 | H12: Paid | L12: Cash
A13: 46235 | B13: P004 | C13: =IFERROR(VLOOKUP(B13, '📋 PRODUCTS'!A:D, 2, FALSE), "") -> Baby Tin 18g | D13: =IFERROR(VLOOKUP(B13, '📋 PRODUCTS'!A:D, 3, FALSE), "") -> Baby Tin | E13: 5 | F13: =IFERROR(VLOOKUP(B13, '📋 PRODUCTS'!A:D, 4, FALSE), "") -> 2000 | G13: =E13*F13 -> 10000 | H13: Paid | L13: Cash
A14: 46240 | B14: P006 | C14: =IFERROR(VLOOKUP(B14, '📋 PRODUCTS'!A:D, 2, FALSE), "") -> Spiced 50g | D14: =IFERROR(VLOOKUP(B14, '📋 PRODUCTS'!A:D, 3, FALSE), "") -> Spiced | E14: 9 | F14: =IFERROR(VLOOKUP(B14, '📋 PRODUCTS'!A:D, 4, FALSE), "") -> 5000 | G14: =E14*F14 -> 45000 | H14: Paid | L14: Cash
A15: 46240 | B15: P009 | C15: =IFERROR(VLOOKUP(B15, '📋 PRODUCTS'!A:D, 2, FALSE), "") -> Quail Eggs 18s | D15: =IFERROR(VLOOKUP(B15, '📋 PRODUCTS'!A:D, 3, FALSE), "") -> Eggs | E15: 2 | F15: =IFERROR(VLOOKUP(B15, '📋 PRODUCTS'!A:D, 4, FALSE), "") -> 8000 | G15: =E15*F15 -> 16000 | H15: Paid | L15: Cash
A16: 46240 | B16: P004 | C16: =IFERROR(VLOOKUP(B16, '📋 PRODUCTS'!A:D, 2, FALSE), "") -> Baby Tin 18g | D16: =IFERROR(VLOOKUP(B16, '📋 PRODUCTS'!A:D, 3, FALSE), "") -> Baby Tin | E16: 7 | F16: =IFERROR(VLOOKUP(B16, '📋 PRODUCTS'!A:D, 4, FALSE), "") -> 2000 | G16: =E16*F16 -> 14000 | H16: Paid | L16: Cash
A17: 46242 | B17: P006 | C17: =IFERROR(VLOOKUP(B17, '📋 PRODUCTS'!A:D, 2, FALSE), "") -> Spiced 50g | D17: =IFERROR(VLOOKUP(B17, '📋 PRODUCTS'!A:D, 3, FALSE), "") -> Spiced | E17: 3 | F17: =IFERROR(VLOOKUP(B17, '📋 PRODUCTS'!A:D, 4, FALSE), "") -> 5000 | G17: =E17*F17 -> 15000 | H17: Paid | L17: Cash
A18: 46244 | B18: P006 | C18: =IFERROR(VLOOKUP(B18, '📋 PRODUCTS'!A:D, 2, FALSE), "") -> Spiced 50g | D18: =IFERROR(VLOOKUP(B18, '📋 PRODUCTS'!A:D, 3, FALSE), "") -> Spiced | E18: 4 | F18: =IFERROR(VLOOKUP(B18, '📋 PRODUCTS'!A:D, 4, FALSE), "") -> 5000 | G18: =E18*F18 -> 20000 | H18: Paid | L18: Cash
A19: 46244 | B19: P004 | C19: =IFERROR(VLOOKUP(B19, '📋 PRODUCTS'!A:D, 2, FALSE), "") -> Baby Tin 18g | D19: =IFERROR(VLOOKUP(B19, '📋 PRODUCTS'!A:D, 3, FALSE), "") -> Baby Tin | E19: 2 | F19: =IFERROR(VLOOKUP(B19, '📋 PRODUCTS'!A:D, 4, FALSE), "") -> 2000 | G19: =E19*F19 -> 4000 | H19: Paid | L19: Cash
A20: 46245 | B20: P004 | C20: =IFERROR(VLOOKUP(B20, '📋 PRODUCTS'!A:D, 2, FALSE), "") -> Baby Tin 18g | D20: =IFERROR(VLOOKUP(B20, '📋 PRODUCTS'!A:D, 3, FALSE), "") -> Baby Tin | E20: 11 | F20: =IFERROR(VLOOKUP(B20, '📋 PRODUCTS'!A:D, 4, FALSE), "") -> 2000 | G20: =E20*F20 -> 22000 | H20: Paid | L20: Cash
A21: 46245 | B21: P006 | C21: =IFERROR(VLOOKUP(B21, '📋 PRODUCTS'!A:D, 2, FALSE), "") -> Spiced 50g | D21: =IFERROR(VLOOKUP(B21, '📋 PRODUCTS'!A:D, 3, FALSE), "") -> Spiced | E21: 14 | F21: =IFERROR(VLOOKUP(B21, '📋 PRODUCTS'!A:D, 4, FALSE), "") -> 5000 | G21: =E21*F21 -> 70000 | H21: Paid | L21: Cash
A22: 46245 | B22: P006 | C22: =IFERROR(VLOOKUP(B22, '📋 PRODUCTS'!A:D, 2, FALSE), "") -> Spiced 50g | D22: =IFERROR(VLOOKUP(B22, '📋 PRODUCTS'!A:D, 3, FALSE), "") -> Spiced | E22: 1 | F22: =IFERROR(VLOOKUP(B22, '📋 PRODUCTS'!A:D, 4, FALSE), "") -> 5000 | G22: =E22*F22 -> 5000 | H22: Paid | L22: Cash | M22: Cleared 12th Aug
A23: 46245 | B23: P006 | C23: =IFERROR(VLOOKUP(B23, '📋 PRODUCTS'!A:D, 2, FALSE), "") -> Spiced 50g | D23: =IFERROR(VLOOKUP(B23, '📋 PRODUCTS'!A:D, 3, FALSE), "") -> Spiced | E23: 1 | F23: =IFERROR(VLOOKUP(B23, '📋 PRODUCTS'!A:D, 4, FALSE), "") -> 5000 | G23: =E23*F23 -> 5000 | H23: Paid | L23: Cash
A24: 46245 | B24: P012 | C24: =IFERROR(VLOOKUP(B24, '📋 PRODUCTS'!A:D, 2, FALSE), "") -> Medium Roast Medium Grind (250g) | D24: =IFERROR(VLOOKUP(B24, '📋 PRODUCTS'!A:D, 3, FALSE), "") -> Black Pack Medium | E24: 1 | F24: =IFERROR(VLOOKUP(B24, '📋 PRODUCTS'!A:D, 4, FALSE), "") -> 25000 | G24: =E24*F24 -> 25000 | H24: Pending | L24: Credit | M24: Tendo
A25: 46245 | B25: P013 | C25: =IFERROR(VLOOKUP(B25, '📋 PRODUCTS'!A:D, 2, FALSE), "") -> Dark Roast Fine Grind (250g) | D25: =IFERROR(VLOOKUP(B25, '📋 PRODUCTS'!A:D, 3, FALSE), "") -> Black Pack Medium | E25: 1 | F25: =IFERROR(VLOOKUP(B25, '📋 PRODUCTS'!A:D, 4, FALSE), "") -> 25000 | G25: =E25*F25 -> 25000 | H25: Pending | L25: Cash | M25: SY
A26: 46245 | B26: P014 | C26: =IFERROR(VLOOKUP(B26, '📋 PRODUCTS'!A:D, 2, FALSE), "") -> Dark Roast Medium Grind (250g) | D26: =IFERROR(VLOOKUP(B26, '📋 PRODUCTS'!A:D, 3, FALSE), "") -> Black Pack Medium | E26: 1 | F26: =IFERROR(VLOOKUP(B26, '📋 PRODUCTS'!A:D, 4, FALSE), "") -> 25000 | G26: =E26*F26 -> 25000 | H26: Pending | L26: Credit | M26: Tendo
A27: 46246 | B27: P006 | C27: =IFERROR(VLOOKUP(B27, '📋 PRODUCTS'!A:D, 2, FALSE), "") -> Spiced 50g | D27: =IFERROR(VLOOKUP(B27, '📋 PRODUCTS'!A:D, 3, FALSE), "") -> Spiced | E27: 15 | F27: =IFERROR(VLOOKUP(B27, '📋 PRODUCTS'!A:D, 4, FALSE), "") -> 5000 | G27: =E27*F27 -> 75000 | H27: Paid | L27: Cash
A28: 46246 | B28: P004 | C28: =IFERROR(VLOOKUP(B28, '📋 PRODUCTS'!A:D, 2, FALSE), "") -> Baby Tin 18g | D28: =IFERROR(VLOOKUP(B28, '📋 PRODUCTS'!A:D, 3, FALSE), "") -> Baby Tin | E28: 23 | F28: =IFERROR(VLOOKUP(B28, '📋 PRODUCTS'!A:D, 4, FALSE), "") -> 2000 | G28: =E28*F28 -> 46000 | H28: Paid | L28: Cash
A29: 46247 | B29: P004 | C29: =IFERROR(VLOOKUP(B29, '📋 PRODUCTS'!A:D, 2, FALSE), "") -> Baby Tin 18g | D29: =IFERROR(VLOOKUP(B29, '📋 PRODUCTS'!A:D, 3, FALSE), "") -> Baby Tin | E29: 8 | F29: =IFERROR(VLOOKUP(B29, '📋 PRODUCTS'!A:D, 4, FALSE), "") -> 2000 | G29: =E29*F29 -> 16000 | H29: Paid | L29: Cash
A30: 46247 | B30: P006 | C30: =IFERROR(VLOOKUP(B30, '📋 PRODUCTS'!A:D, 2, FALSE), "") -> Spiced 50g | D30: =IFERROR(VLOOKUP(B30, '📋 PRODUCTS'!A:D, 3, FALSE), "") -> Spiced | E30: 2 | F30: =IFERROR(VLOOKUP(B30, '📋 PRODUCTS'!A:D, 4, FALSE), "") -> 5000 | G30: =E30*F30 -> 10000 | H30: Paid | L30: Cash
A31: 46247 | B31: P006 | C31: =IFERROR(VLOOKUP(B31, '📋 PRODUCTS'!A:D, 2, FALSE), "") -> Spiced 50g | D31: =IFERROR(VLOOKUP(B31, '📋 PRODUCTS'!A:D, 3, FALSE), "") -> Spiced | E31: 1 | F31: =IFERROR(VLOOKUP(B31, '📋 PRODUCTS'!A:D, 4, FALSE), "") -> 5000 | G31: =E31*F31 -> 5000 | H31: Paid | L31: Cash
A32: 46248 | B32: P006 | C32: =IFERROR(VLOOKUP(B32, '📋 PRODUCTS'!A:D, 2, FALSE), "") -> Spiced 50g | D32: =IFERROR(VLOOKUP(B32, '📋 PRODUCTS'!A:D, 3, FALSE), "") -> Spiced | E32: 11 | F32: =IFERROR(VLOOKUP(B32, '📋 PRODUCTS'!A:D, 4, FALSE), "") -> 5000 | G32: =E32*F32 -> 55000 | H32: Paid | L32: Cash
A33: 46248 | B33: P004 | C33: =IFERROR(VLOOKUP(B33, '📋 PRODUCTS'!A:D, 2, FALSE), "") -> Baby Tin 18g | D33: =IFERROR(VLOOKUP(B33, '📋 PRODUCTS'!A:D, 3, FALSE), "") -> Baby Tin | E33: 5 | F33: =IFERROR(VLOOKUP(B33, '📋 PRODUCTS'!A:D, 4, FALSE), "") -> 2000 | G33: =E33*F33 -> 10000 | H33: Paid | L33: Cash
A34: 46250 | B34: P007 | C34: =IFERROR(VLOOKUP(B34, '📋 PRODUCTS'!A:D, 2, FALSE), "") -> Black Pack 100g | D34: =IFERROR(VLOOKUP(B34, '📋 PRODUCTS'!A:D, 3, FALSE), "") -> Black Pack Small | E34: 2 | F34: =IFERROR(VLOOKUP(B34, '📋 PRODUCTS'!A:D, 4, FALSE), "") -> 10000 | G34: =E34*F34 -> 20000 | H34: Paid | L34: Cash
A35: 46250 | B35: P006 | C35: =IFERROR(VLOOKUP(B35, '📋 PRODUCTS'!A:D, 2, FALSE), "") -> Spiced 50g | D35: =IFERROR(VLOOKUP(B35, '📋 PRODUCTS'!A:D, 3, FALSE), "") -> Spiced | E35: 1 | F35: =IFERROR(VLOOKUP(B35, '📋 PRODUCTS'!A:D, 4, FALSE), "") -> 5000 | G35: =E35*F35 -> 5000 | H35: Paid | L35: Cash
A36: 46250 | B36: P008 | C36: =IFERROR(VLOOKUP(B36, '📋 PRODUCTS'!A:D, 2, FALSE), "") -> MiDAY Combo | D36: =IFERROR(VLOOKUP(B36, '📋 PRODUCTS'!A:D, 3, FALSE), "") -> Combo | E36: 1 | F36: =IFERROR(VLOOKUP(B36, '📋 PRODUCTS'!A:D, 4, FALSE), "") -> 12000 | G36: =E36*F36 -> 12000 | H36: Paid | L36: Cash
A37: 46255 | B37: P006 | C37: =IFERROR(VLOOKUP(B37, '📋 PRODUCTS'!A:D, 2, FALSE), "") -> Spiced 50g | D37: =IFERROR(VLOOKUP(B37, '📋 PRODUCTS'!A:D, 3, FALSE), "") -> Spiced | E37: 2 | F37: =IFERROR(VLOOKUP(B37, '📋 PRODUCTS'!A:D, 4, FALSE), "") -> 5000 | G37: =E37*F37 -> 10000 | H37: Paid | L37: Cash
A38: 46255 | B38: P004 | C38: =IFERROR(VLOOKUP(B38, '📋 PRODUCTS'!A:D, 2, FALSE), "") -> Baby Tin 18g | D38: =IFERROR(VLOOKUP(B38, '📋 PRODUCTS'!A:D, 3, FALSE), "") -> Baby Tin | E38: 3 | F38: =IFERROR(VLOOKUP(B38, '📋 PRODUCTS'!A:D, 4, FALSE), "") -> 2000 | G38: =E38*F38 -> 6000 | H38: Paid | L38: Cash
C39: =IFERROR(VLOOKUP(B39, '📋 PRODUCTS'!A:D, 2, FALSE), "") | D39: =IFERROR(VLOOKUP(B39, '📋 PRODUCTS'!A:D, 3, FALSE), "") | F39: =IFERROR(VLOOKUP(B39, '📋 PRODUCTS'!A:D, 4, FALSE), "") | G39: =E39*F39 -> 0
C40: =IFERROR(VLOOKUP(B40, '📋 PRODUCTS'!A:D, 2, FALSE), "") | D40: =IFERROR(VLOOKUP(B40, '📋 PRODUCTS'!A:D, 3, FALSE), "") | F40: =IFERROR(VLOOKUP(B40, '📋 PRODUCTS'!A:D, 4, FALSE), "") | G40: =E40*F40 -> 0
...

Sheet 🔧 ASSETS
A1: Purchase Date | B1: Asset Category | C1: Asset Name | D1: Supplier | E1: Serial/Tag No. | F1: Quantity | G1: Unit Price (UGX) | H1: Total Cost (UGX) | I1: Location | J1: Condition | K1: Depreciation (Monthly) | L1: Notes
A2: 46182 | C2: Scissor | F2: 1 | G2: 2000 | H2: 70000 | J2: Active
A3: 46182 | C3: Sealer | F3: 1 | G3: 70000 | H3: 70000 | J3: Active
A4: 46182 | C4: Weighing scale | F4: 1 | G4: 30000 | H4: 30000 | J4: Active
C5: Coffee machine | F5: 1 | G5: 330000 | H5: 330000
C6: Grinder | F6: 1 | G6: 50000 | H6: 50000
C7: Display | F7: 1 | G7: 500000
C8: Chairs | F8: 4
C9: Wood boards | F9: 5 | H9: 40000
C10: Aprons | F10: 2 | H10: 24000

Sheet 📊 WEEKLY PERFORMANCE
A1: Week Starting | B1: Week Ending | C1: Revenue | D1: COGS | E1: Gross Profit | F1: Gross Margin % | G1: Opex | H1: Net Profit | I1: Net Margin % | J1: Units Sold | K1: Top Product | L1: Growth % | M1: Target vs Actual
A2: 46025.853 | B2: 46031.853 | C2: =SUMIFS(MASTER_SALES!G:G, MASTER_SALES!A:A, ">="&A2, MASTER_SALES!A:A, "<="&B2) -> 0 | D2: =SUMIFS(MASTER_SALES!N:N, MASTER_SALES!A:A, ">="&A2, MASTER_SALES!A:A, "<="&B2) -> 0 | E2: =C2-D2 -> 0 | F2: =IFERROR(E2/C2,0) -> 0 | G2: =SUMIFS('💰 EXPENSES'!F:F, '💰 EXPENSES'!A:A, ">="&A2, '💰 EXPENSES'!A:A, "<="&B2) -> 0 | H2: =E2-G2 -> 0 | I2: =IFERROR(H2/C2,0) -> 0 | J2: =SUMIFS(MASTER_SALES!E:E, MASTER_SALES!A:A, ">="&A2, MASTER_SALES!A:A, "<="&B2) -> 0 | L2: =IFERROR((C2-#REF!)/#REF!,0) -> 0
A3: 46032.853 | B3: 46038.853 | C3: =SUMIFS(MASTER_SALES!G:G, MASTER_SALES!A:A, ">="&A3, MASTER_SALES!A:A, "<="&B3) -> 0 | D3: =SUMIFS(MASTER_SALES!N:N, MASTER_SALES!A:A, ">="&A3, MASTER_SALES!A:A, "<="&B3) -> 0 | E3: =C3-D3 -> 0 | F3: =IFERROR(E3/C3,0) -> 0 | G3: =SUMIFS('💰 EXPENSES'!F:F, '💰 EXPENSES'!A:A, ">="&A3, '💰 EXPENSES'!A:A, "<="&B3) -> 0 | H3: =E3-G3 -> 0 | I3: =IFERROR(H3/C3,0) -> 0 | J3: =SUMIFS(MASTER_SALES!E:E, MASTER_SALES!A:A, ">="&A3, MASTER_SALES!A:A, "<="&B3) -> 0 | L3: =IFERROR((C3-C2)/C2,0) -> 0
A4: 46039.853 | B4: 46045.853 | C4: =SUMIFS(MASTER_SALES!G:G, MASTER_SALES!A:A, ">="&A4, MASTER_SALES!A:A, "<="&B4) -> 0 | D4: =SUMIFS(MASTER_SALES!N:N, MASTER_SALES!A:A, ">="&A4, MASTER_SALES!A:A, "<="&B4) -> 0 | E4: =C4-D4 -> 0 | F4: =IFERROR(E4/C4,0) -> 0 | G4: =SUMIFS('💰 EXPENSES'!F:F, '💰 EXPENSES'!A:A, ">="&A4, '💰 EXPENSES'!A:A, "<="&B4) -> 0 | H4: =E4-G4 -> 0 | I4: =IFERROR(H4/C4,0) -> 0 | J4: =SUMIFS(MASTER_SALES!E:E, MASTER_SALES!A:A, ">="&A4, MASTER_SALES!A:A, "<="&B4) -> 0 | L4: =IFERROR((C4-C3)/C3,0) -> 0
A5: 46046.853 | B5: 46052.853 | C5: =SUMIFS(MASTER_SALES!G:G, MASTER_SALES!A:A, ">="&A5, MASTER_SALES!A:A, "<="&B5) -> 0 | D5: =SUMIFS(MASTER_SALES!N:N, MASTER_SALES!A:A, ">="&A5, MASTER_SALES!A:A, "<="&B5) -> 0 | E5: =C5-D5 -> 0 | F5: =IFERROR(E5/C5,0) -> 0 | G5: =SUMIFS('💰 EXPENSES'!F:F, '💰 EXPENSES'!A:A, ">="&A5, '💰 EXPENSES'!A:A, "<="&B5) -> 0 | H5: =E5-G5 -> 0 | I5: =IFERROR(H5/C5,0) -> 0 | J5: =SUMIFS(MASTER_SALES!E:E, MASTER_SALES!A:A, ">="&A5, MASTER_SALES!A:A, "<="&B5) -> 0 | L5: =IFERROR((C5-C4)/C4,0) -> 0
A6: 46053.853 | B6: 46059.853 | C6: =SUMIFS(MASTER_SALES!G:G, MASTER_SALES!A:A, ">="&A6, MASTER_SALES!A:A, "<="&B6) -> 0 | D6: =SUMIFS(MASTER_SALES!N:N, MASTER_SALES!A:A, ">="&A6, MASTER_SALES!A:A, "<="&B6) -> 0 | E6: =C6-D6 -> 0 | F6: =IFERROR(E6/C6,0) -> 0 | G6: =SUMIFS('💰 EXPENSES'!F:F, '💰 EXPENSES'!A:A, ">="&A6, '💰 EXPENSES'!A:A, "<="&B6) -> 0 | H6: =E6-G6 -> 0 | I6: =IFERROR(H6/C6,0) -> 0 | J6: =SUMIFS(MASTER_SALES!E:E, MASTER_SALES!A:A, ">="&A6, MASTER_SALES!A:A, "<="&B6) -> 0 | L6: =IFERROR((C6-C5)/C5,0) -> 0
A7: 46060.853 | B7: 46066.853 | C7: =SUMIFS(MASTER_SALES!G:G, MASTER_SALES!A:A, ">="&A7, MASTER_SALES!A:A, "<="&B7) -> 0 | D7: =SUMIFS(MASTER_SALES!N:N, MASTER_SALES!A:A, ">="&A7, MASTER_SALES!A:A, "<="&B7) -> 0 | E7: =C7-D7 -> 0 | F7: =IFERROR(E7/C7,0) -> 0 | G7: =SUMIFS('💰 EXPENSES'!F:F, '💰 EXPENSES'!A:A, ">="&A7, '💰 EXPENSES'!A:A, "<="&B7) -> 0 | H7: =E7-G7 -> 0 | I7: =IFERROR(H7/C7,0) -> 0 | J7: =SUMIFS(MASTER_SALES!E:E, MASTER_SALES!A:A, ">="&A7, MASTER_SALES!A:A, "<="&B7) -> 0 | L7: =IFERROR((C7-C6)/C6,0) -> 0
A8: 46067.853 | B8: 46073.853 | C8: =SUMIFS(MASTER_SALES!G:G, MASTER_SALES!A:A, ">="&A8, MASTER_SALES!A:A, "<="&B8) -> 0 | D8: =SUMIFS(MASTER_SALES!N:N, MASTER_SALES!A:A, ">="&A8, MASTER_SALES!A:A, "<="&B8) -> 0 | E8: =C8-D8 -> 0 | F8: =IFERROR(E8/C8,0) -> 0 | G8: =SUMIFS('💰 EXPENSES'!F:F, '💰 EXPENSES'!A:A, ">="&A8, '💰 EXPENSES'!A:A, "<="&B8) -> 0 | H8: =E8-G8 -> 0 | I8: =IFERROR(H8/C8,0) -> 0 | J8: =SUMIFS(MASTER_SALES!E:E, MASTER_SALES!A:A, ">="&A8, MASTER_SALES!A:A, "<="&B8) -> 0 | L8: =IFERROR((C8-C7)/C7,0) -> 0
A9: 46074.853 | B9: 46080.853 | C9: =SUMIFS(MASTER_SALES!G:G, MASTER_SALES!A:A, ">="&A9, MASTER_SALES!A:A, "<="&B9) -> 0 | D9: =SUMIFS(MASTER_SALES!N:N, MASTER_SALES!A:A, ">="&A9, MASTER_SALES!A:A, "<="&B9) -> 0 | E9: =C9-D9 -> 0 | F9: =IFERROR(E9/C9,0) -> 0 | G9: =SUMIFS('💰 EXPENSES'!F:F, '💰 EXPENSES'!A:A, ">="&A9, '💰 EXPENSES'!A:A, "<="&B9) -> 0 | H9: =E9-G9 -> 0 | I9: =IFERROR(H9/C9,0) -> 0 | J9: =SUMIFS(MASTER_SALES!E:E, MASTER_SALES!A:A, ">="&A9, MASTER_SALES!A:A, "<="&B9) -> 0 | L9: =IFERROR((C9-C8)/C8,0) -> 0
A10: 46081.853 | B10: 46087.853 | C10: =SUMIFS(MASTER_SALES!G:G, MASTER_SALES!A:A, ">="&A10, MASTER_SALES!A:A, "<="&B10) -> 0 | D10: =SUMIFS(MASTER_SALES!N:N, MASTER_SALES!A:A, ">="&A10, MASTER_SALES!A:A, "<="&B10) -> 0 | E10: =C10-D10 -> 0 | F10: =IFERROR(E10/C10,0) -> 0 | G10: =SUMIFS('💰 EXPENSES'!F:F, '💰 EXPENSES'!A:A, ">="&A10, '💰 EXPENSES'!A:A, "<="&B10) -> 0 | H10: =E10-G10 -> 0 | I10: =IFERROR(H10/C10,0) -> 0 | J10: =SUMIFS(MASTER_SALES!E:E, MASTER_SALES!A:A, ">="&A10, MASTER_SALES!A:A, "<="&B10) -> 0 | L10: =IFERROR((C10-C9)/C9,0) -> 0
A11: 46088.853 | B11: 46094.853 | C11: =SUMIFS(MASTER_SALES!G:G, MASTER_SALES!A:A, ">="&A11, MASTER_SALES!A:A, "<="&B11) -> 0 | D11: =SUMIFS(MASTER_SALES!N:N, MASTER_SALES!A:A, ">="&A11, MASTER_SALES!A:A, "<="&B11) -> 0 | E11: =C11-D11 -> 0 | F11: =IFERROR(E11/C11,0) -> 0 | G11: =SUMIFS('💰 EXPENSES'!F:F, '💰 EXPENSES'!A:A, ">="&A11, '💰 EXPENSES'!A:A, "<="&B11) -> 0 | H11: =E11-G11 -> 0 | I11: =IFERROR(H11/C11,0) -> 0 | J11: =SUMIFS(MASTER_SALES!E:E, MASTER_SALES!A:A, ">="&A11, MASTER_SALES!A:A, "<="&B11) -> 0 | L11: =IFERROR((C11-C10)/C10,0) -> 0
A12: 46095.853 | B12: 46101.853 | C12: =SUMIFS(MASTER_SALES!G:G, MASTER_SALES!A:A, ">="&A12, MASTER_SALES!A:A, "<="&B12) -> 0 | D12: =SUMIFS(MASTER_SALES!N:N, MASTER_SALES!A:A, ">="&A12, MASTER_SALES!A:A, "<="&B12) -> 0 | E12: =C12-D12 -> 0 | F12: =IFERROR(E12/C12,0) -> 0 | G12: =SUMIFS('💰 EXPENSES'!F:F, '💰 EXPENSES'!A:A, ">="&A12, '💰 EXPENSES'!A:A, "<="&B12) -> 0 | H12: =E12-G12 -> 0 | I12: =IFERROR(H12/C12,0) -> 0 | J12: =SUMIFS(MASTER_SALES!E:E, MASTER_SALES!A:A, ">="&A12, MASTER_SALES!A:A, "<="&B12) -> 0 | L12: =IFERROR((C12-C11)/C11,0) -> 0
A13: 46102.853 | B13: 46108.853 | C13: =SUMIFS(MASTER_SALES!G:G, MASTER_SALES!A:A, ">="&A13, MASTER_SALES!A:A, "<="&B13) -> 0 | D13: =SUMIFS(MASTER_SALES!N:N, MASTER_SALES!A:A, ">="&A13, MASTER_SALES!A:A, "<="&B13) -> 0 | E13: =C13-D13 -> 0 | F13: =IFERROR(E13/C13,0) -> 0 | G13: =SUMIFS('💰 EXPENSES'!F:F, '💰 EXPENSES'!A:A, ">="&A13, '💰 EXPENSES'!A:A, "<="&B13) -> 0 | H13: =E13-G13 -> 0 | I13: =IFERROR(H13/C13,0) -> 0 | J13: =SUMIFS(MASTER_SALES!E:E, MASTER_SALES!A:A, ">="&A13, MASTER_SALES!A:A, "<="&B13) -> 0 | L13: =IFERROR((C13-C12)/C12,0) -> 0
A14: 46109.853 | B14: 46115.853 | C14: =SUMIFS(MASTER_SALES!G:G, MASTER_SALES!A:A, ">="&A14, MASTER_SALES!A:A, "<="&B14) -> 0 | D14: =SUMIFS(MASTER_SALES!N:N, MASTER_SALES!A:A, ">="&A14, MASTER_SALES!A:A, "<="&B14) -> 0 | E14: =C14-D14 -> 0 | F14: =IFERROR(E14/C14,0) -> 0 | G14: =SUMIFS('💰 EXPENSES'!F:F, '💰 EXPENSES'!A:A, ">="&A14, '💰 EXPENSES'!A:A, "<="&B14) -> 0 | H14: =E14-G14 -> 0 | I14: =IFERROR(H14/C14,0) -> 0 | J14: =SUMIFS(MASTER_SALES!E:E, MASTER_SALES!A:A, ">="&A14, MASTER_SALES!A:A, "<="&B14) -> 0 | L14: =IFERROR((C14-C13)/C13,0) -> 0
... A100: 46711 | B100: 46717 | C100: =SUMIFS(MASTER_SALES!G:G, MASTER_SALES!A:A, ">="&A100, MASTER_SALES!A:A, "<="&B100) -> 0 | D100: =SUMIFS(MASTER_SALES!N:N, MASTER_SALES!A:A, ">="&A100, MASTER_SALES!A:A, "<="&B100) -> 0 | E100: =C100-D100 -> 0 | F100: =IFERROR(E100/C100,0) -> 0 | G100: =SUMIFS('💰 EXPENSES'!F:F, '💰 EXPENSES'!A:A, ">="&A100, '💰 EXPENSES'!A:A, "<="&B100) -> 0 | H100: =E100-G100 -> 0 | I100: =IFERROR(H100/C100,0) -> 0 | J100: =SUMIFS(MASTER_SALES!E:E, MASTER_SALES!A:A, ">="&A100, MASTER_SALES!A:A, "<="&B100) -> 0 | L100: =IFERROR((C100-C99)/C99,0) -> 0

Sheet 📈 MONTHLY PERFORMANCE
A1: Month | B1: Revenue | C1: COGS | D1: Gross Profit | E1: Gross Margin % | F1: Opex | G1: Net Profit | H1: Net Margin % | I1: Units Sold | J1: Avg Weekly Revenue | K1: Growth % | L1: Target vs Actual
A2: 46722 | B2: =SUMIFS(MASTER_SALES!G:G, MASTER_SALES!A:A, ">="&DATE(YEAR(A2),MONTH(A2),1), MASTER_SALES!A:A, "<="&EOMONTH(A2,0)) -> 0 | C2: =SUMIFS(MASTER_SALES!N:N, MASTER_SALES!A:A, ">="&DATE(YEAR(A2),MONTH(A2),1), MASTER_SALES!A:A, "<="&EOMONTH(A2,0)) -> 0 | D2: =B2-C2 -> 0 | E2: =IFERROR(D2/B2,0) -> 0 | F2: =SUMIFS('💰 EXPENSES'!F:F, '💰 EXPENSES'!A:A, ">="&DATE(YEAR(A2),MONTH(A2),1), '💰 EXPENSES'!A:A, "<="&EOMONTH(A2,0)) -> 0 | G2: =D2-F2 -> 0 | H2: =IFERROR(G2/B2,0) -> 0 | I2: =SUMIFS(MASTER_SALES!E:E, MASTER_SALES!A:A, ">="&DATE(YEAR(A2),MONTH(A2),1), MASTER_SALES!A:A, "<="&EOMONTH(A2,0)) -> 0 | J2: =B2/4 -> 0 | K2: =IFERROR((B2-B1)/B1,0) -> 0
A3: 46692 | B3: =SUMIFS(MASTER_SALES!G:G, MASTER_SALES!A:A, ">="&DATE(YEAR(A3),MONTH(A3),1), MASTER_SALES!A:A, "<="&EOMONTH(A3,0)) -> 0 | C3: =SUMIFS(MASTER_SALES!N:N, MASTER_SALES!A:A, ">="&DATE(YEAR(A3),MONTH(A3),1), MASTER_SALES!A:A, "<="&EOMONTH(A3,0)) -> 0 | D3: =B3-C3 -> 0 | E3: =IFERROR(D3/B3,0) -> 0 | F3: =SUMIFS('💰 EXPENSES'!F:F, '💰 EXPENSES'!A:A, ">="&DATE(YEAR(A3),MONTH(A3),1), '💰 EXPENSES'!A:A, "<="&EOMONTH(A3,0)) -> 0 | G3: =D3-F3 -> 0 | H3: =IFERROR(G3/B3,0) -> 0 | I3: =SUMIFS(MASTER_SALES!E:E, MASTER_SALES!A:A, ">="&DATE(YEAR(A3),MONTH(A3),1), MASTER_SALES!A:A, "<="&EOMONTH(A3,0)) -> 0 | J3: =B3/4 -> 0 | K3: =IFERROR((B3-B2)/B2,0) -> 0
A4: 46661 | B4: =SUMIFS(MASTER_SALES!G:G, MASTER_SALES!A:A, ">="&DATE(YEAR(A4),MONTH(A4),1), MASTER_SALES!A:A, "<="&EOMONTH(A4,0)) -> 0 | C4: =SUMIFS(MASTER_SALES!N:N, MASTER_SALES!A:A, ">="&DATE(YEAR(A4),MONTH(A4),1), MASTER_SALES!A:A, "<="&EOMONTH(A4,0)) -> 0 | D4: =B4-C4 -> 0 | E4: =IFERROR(D4/B4,0) -> 0 | F4: =SUMIFS('💰 EXPENSES'!F:F, '💰 EXPENSES'!A:A, ">="&DATE(YEAR(A4),MONTH(A4),1), '💰 EXPENSES'!A:A, "<="&EOMONTH(A4,0)) -> 0 | G4: =D4-F4 -> 0 | H4: =IFERROR(G4/B4,0) -> 0 | I4: =SUMIFS(MASTER_SALES!E:E, MASTER_SALES!A:A, ">="&DATE(YEAR(A4),MONTH(A4),1), MASTER_SALES!A:A, "<="&EOMONTH(A4,0)) -> 0 | J4: =B4/4 -> 0 | K4: =IFERROR((B4-B3)/B3,0) -> 0
A5: 46631 | B5: =SUMIFS(MASTER_SALES!G:G, MASTER_SALES!A:A, ">="&DATE(YEAR(A5),MONTH(A5),1), MASTER_SALES!A:A, "<="&EOMONTH(A5,0)) -> 0 | C5: =SUMIFS(MASTER_SALES!N:N, MASTER_SALES!A:A, ">="&DATE(YEAR(A5),MONTH(A5),1), MASTER_SALES!A:A, "<="&EOMONTH(A5,0)) -> 0 | D5: =B5-C5 -> 0 | E5: =IFERROR(D5/B5,0) -> 0 | F5: =SUMIFS('💰 EXPENSES'!F:F, '💰 EXPENSES'!A:A, ">="&DATE(YEAR(A5),MONTH(A5),1), '💰 EXPENSES'!A:A, "<="&EOMONTH(A5,0)) -> 0 | G5: =D5-F5 -> 0 | H5: =IFERROR(G5/B5,0) -> 0 | I5: =SUMIFS(MASTER_SALES!E:E, MASTER_SALES!A:A, ">="&DATE(YEAR(A5),MONTH(A5),1), MASTER_SALES!A:A, "<="&EOMONTH(A5,0)) -> 0 | J5: =B5/4 -> 0 | K5: =IFERROR((B5-B4)/B4,0) -> 0
A6: 46600 | B6: =SUMIFS(MASTER_SALES!G:G, MASTER_SALES!A:A, ">="&DATE(YEAR(A6),MONTH(A6),1), MASTER_SALES!A:A, "<="&EOMONTH(A6,0)) -> 0 | C6: =SUMIFS(MASTER_SALES!N:N, MASTER_SALES!A:A, ">="&DATE(YEAR(A6),MONTH(A6),1), MASTER_SALES!A:A, "<="&EOMONTH(A6,0)) -> 0 | D6: =B6-C6 -> 0 | E6: =IFERROR(D6/B6,0) -> 0 | F6: =SUMIFS('💰 EXPENSES'!F:F, '💰 EXPENSES'!A:A, ">="&DATE(YEAR(A6),MONTH(A6),1), '💰 EXPENSES'!A:A, "<="&EOMONTH(A6,0)) -> 0 | G6: =D6-F6 -> 0 | H6: =IFERROR(G6/B6,0) -> 0 | I6: =SUMIFS(MASTER_SALES!E:E, MASTER_SALES!A:A, ">="&DATE(YEAR(A6),MONTH(A6),1), MASTER_SALES!A:A, "<="&EOMONTH(A6,0)) -> 0 | J6: =B6/4 -> 0 | K6: =IFERROR((B6-B5)/B5,0) -> 0
A7: 46569 | B7: =SUMIFS(MASTER_SALES!G:G, MASTER_SALES!A:A, ">="&DATE(YEAR(A7),MONTH(A7),1), MASTER_SALES!A:A, "<="&EOMONTH(A7,0)) -> 0 | C7: =SUMIFS(MASTER_SALES!N:N, MASTER_SALES!A:A, ">="&DATE(YEAR(A7),MONTH(A7),1), MASTER_SALES!A:A, "<="&EOMONTH(A7,0)) -> 0 | D7: =B7-C7 -> 0 | E7: =IFERROR(D7/B7,0) -> 0 | F7: =SUMIFS('💰 EXPENSES'!F:F, '💰 EXPENSES'!A:A, ">="&DATE(YEAR(A7),MONTH(A7),1), '💰 EXPENSES'!A:A, "<="&EOMONTH(A7,0)) -> 0 | G7: =D7-F7 -> 0 | H7: =IFERROR(G7/B7,0) -> 0 | I7: =SUMIFS(MASTER_SALES!E:E, MASTER_SALES!A:A, ">="&DATE(YEAR(A7),MONTH(A7),1), MASTER_SALES!A:A, "<="&EOMONTH(A7,0)) -> 0 | J7: =B7/4 -> 0 | K7: =IFERROR((B7-B6)/B6,0) -> 0
A8: 46539 | B8: =SUMIFS(MASTER_SALES!G:G, MASTER_SALES!A:A, ">="&DATE(YEAR(A8),MONTH(A8),1), MASTER_SALES!A:A, "<="&EOMONTH(A8,0)) -> 0 | C8: =SUMIFS(MASTER_SALES!N:N, MASTER_SALES!A:A, ">="&DATE(YEAR(A8),MONTH(A8),1), MASTER_SALES!A:A, "<="&EOMONTH(A8,0)) -> 0 | D8: =B8-C8 -> 0 | E8: =IFERROR(D8/B8,0) -> 0 | F8: =SUMIFS('💰 EXPENSES'!F:F, '💰 EXPENSES'!A:A, ">="&DATE(YEAR(A8),MONTH(A8),1), '💰 EXPENSES'!A:A, "<="&EOMONTH(A8,0)) -> 0 | G8: =D8-F8 -> 0 | H8: =IFERROR(G8/B8,0) -> 0 | I8: =SUMIFS(MASTER_SALES!E:E, MASTER_SALES!A:A, ">="&DATE(YEAR(A8),MONTH(A8),1), MASTER_SALES!A:A, "<="&EOMONTH(A8,0)) -> 0 | J8: =B8/4 -> 0 | K8: =IFERROR((B8-B7)/B7,0) -> 0
A9: 46508 | B9: =SUMIFS(MASTER_SALES!G:G, MASTER_SALES!A:A, ">="&DATE(YEAR(A9),MONTH(A9),1), MASTER_SALES!A:A, "<="&EOMONTH(A9,0)) -> 0 | C9: =SUMIFS(MASTER_SALES!N:N, MASTER_SALES!A:A, ">="&DATE(YEAR(A9),MONTH(A9),1), MASTER_SALES!A:A, "<="&EOMONTH(A9,0)) -> 0 | D9: =B9-C9 -> 0 | E9: =IFERROR(D9/B9,0) -> 0 | F9: =SUMIFS('💰 EXPENSES'!F:F, '💰 EXPENSES'!A:A, ">="&DATE(YEAR(A9),MONTH(A9),1), '💰 EXPENSES'!A:A, "<="&EOMONTH(A9,0)) -> 0 | G9: =D9-F9 -> 0 | H9: =IFERROR(G9/B9,0) -> 0 | I9: =SUMIFS(MASTER_SALES!E:E, MASTER_SALES!A:A, ">="&DATE(YEAR(A9),MONTH(A9),1), MASTER_SALES!A:A, "<="&EOMONTH(A9,0)) -> 0 | J9: =B9/4 -> 0 | K9: =IFERROR((B9-B8)/B8,0) -> 0
A10: 46478 | B10: =SUMIFS(MASTER_SALES!G:G, MASTER_SALES!A:A, ">="&DATE(YEAR(A10),MONTH(A10),1), MASTER_SALES!A:A, "<="&EOMONTH(A10,0)) -> 0 | C10: =SUMIFS(MASTER_SALES!N:N, MASTER_SALES!A:A, ">="&DATE(YEAR(A10),MONTH(A10),1), MASTER_SALES!A:A, "<="&EOMONTH(A10,0)) -> 0 | D10: =B10-C10 -> 0 | E10: =IFERROR(D10/B10,0) -> 0 | F10: =SUMIFS('💰 EXPENSES'!F:F, '💰 EXPENSES'!A:A, ">="&DATE(YEAR(A10),MONTH(A10),1), '💰 EXPENSES'!A:A, "<="&EOMONTH(A10,0)) -> 0 | G10: =D10-F10 -> 0 | H10: =IFERROR(G10/B10,0) -> 0 | I10: =SUMIFS(MASTER_SALES!E:E, MASTER_SALES!A:A, ">="&DATE(YEAR(A10),MONTH(A10),1), MASTER_SALES!A:A, "<="&EOMONTH(A10,0)) -> 0 | J10: =B10/4 -> 0 | K10: =IFERROR((B10-B9)/B9,0) -> 0
A11: 46447 | B11: =SUMIFS(MASTER_SALES!G:G, MASTER_SALES!A:A, ">="&DATE(YEAR(A11),MONTH(A11),1), MASTER_SALES!A:A, "<="&EOMONTH(A11,0)) -> 0 | C11: =SUMIFS(MASTER_SALES!N:N, MASTER_SALES!A:A, ">="&DATE(YEAR(A11),MONTH(A11),1), MASTER_SALES!A:A, "<="&EOMONTH(A11,0)) -> 0 | D11: =B11-C11 -> 0 | E11: =IFERROR(D11/B11,0) -> 0 | F11: =SUMIFS('💰 EXPENSES'!F:F, '💰 EXPENSES'!A:A, ">="&DATE(YEAR(A11),MONTH(A11),1), '💰 EXPENSES'!A:A, "<="&EOMONTH(A11,0)) -> 0 | G11: =D11-F11 -> 0 | H11: =IFERROR(G11/B11,0) -> 0 | I11: =SUMIFS(MASTER_SALES!E:E, MASTER_SALES!A:A, ">="&DATE(YEAR(A11),MONTH(A11),1), MASTER_SALES!A:A, "<="&EOMONTH(A11,0)) -> 0 | J11: =B11/4 -> 0 | K11: =IFERROR((B11-B10)/B10,0) -> 0
A12: 46419 | B12: =SUMIFS(MASTER_SALES!G:G, MASTER_SALES!A:A, ">="&DATE(YEAR(A12),MONTH(A12),1), MASTER_SALES!A:A, "<="&EOMONTH(A12,0)) -> 0 | C12: =SUMIFS(MASTER_SALES!N:N, MASTER_SALES!A:A, ">="&DATE(YEAR(A12),MONTH(A12),1), MASTER_SALES!A:A, "<="&EOMONTH(A12,0)) -> 0 | D12: =B12-C12 -> 0 | E12: =IFERROR(D12/B12,0) -> 0 | F12: =SUMIFS('💰 EXPENSES'!F:F, '💰 EXPENSES'!A:A, ">="&DATE(YEAR(A12),MONTH(A12),1), '💰 EXPENSES'!A:A, "<="&EOMONTH(A12,0)) -> 0 | G12: =D12-F12 -> 0 | H12: =IFERROR(G12/B12,0) -> 0 | I12: =SUMIFS(MASTER_SALES!E:E, MASTER_SALES!A:A, ">="&DATE(YEAR(A12),MONTH(A12),1), MASTER_SALES!A:A, "<="&EOMONTH(A12,0)) -> 0 | J12: =B12/4 -> 0 | K12: =IFERROR((B12-B11)/B11,0) -> 0
A13: 46388 | B13: =SUMIFS(MASTER_SALES!G:G, MASTER_SALES!A:A, ">="&DATE(YEAR(A13),MONTH(A13),1), MASTER_SALES!A:A, "<="&EOMONTH(A13,0)) -> 0 | C13: =SUMIFS(MASTER_SALES!N:N, MASTER_SALES!A:A, ">="&DATE(YEAR(A13),MONTH(A13),1), MASTER_SALES!A:A, "<="&EOMONTH(A13,0)) -> 0 | D13: =B13-C13 -> 0 | E13: =IFERROR(D13/B13,0) -> 0 | F13: =SUMIFS('💰 EXPENSES'!F:F, '💰 EXPENSES'!A:A, ">="&DATE(YEAR(A13),MONTH(A13),1), '💰 EXPENSES'!A:A, "<="&EOMONTH(A13,0)) -> 0 | G13: =D13-F13 -> 0 | H13: =IFERROR(G13/B13,0) -> 0 | I13: =SUMIFS(MASTER_SALES!E:E, MASTER_SALES!A:A, ">="&DATE(YEAR(A13),MONTH(A13),1), MASTER_SALES!A:A, "<="&EOMONTH(A13,0)) -> 0 | J13: =B13/4 -> 0 | K13: =IFERROR((B13-B12)/B12,0) -> 0
... A25: 46023.853 | B25: =SUMIFS(MASTER_SALES!G:G, MASTER_SALES!A:A, ">="&DATE(YEAR(A25),MONTH(A25),1), MASTER_SALES!A:A, "<="&EOMONTH(A25,0)) -> 0 | C25: =SUMIFS(MASTER_SALES!N:N, MASTER_SALES!A:A, ">="&DATE(YEAR(A25),MONTH(A25),1), MASTER_SALES!A:A, "<="&EOMONTH(A25,0)) -> 0 | D25: =B25-C25 -> 0 | E25: =IFERROR(D25/B25,0) -> 0 | F25: =SUMIFS('💰 EXPENSES'!F:F, '💰 EXPENSES'!A:A, ">="&DATE(YEAR(A25),MONTH(A25),1), '💰 EXPENSES'!A:A, "<="&EOMONTH(A25,0)) -> 0 | G25: =D25-F25 -> 0 | H25: =IFERROR(G25/B25,0) -> 0 | I25: =SUMIFS(MASTER_SALES!E:E, MASTER_SALES!A:A, ">="&DATE(YEAR(A25),MONTH(A25),1), MASTER_SALES!A:A, "<="&EOMONTH(A25,0)) -> 0 | J25: =B25/4 -> 0 | K25: =IFERROR((B25-B24)/B24,0) -> 0

Sheet 📊 COGS
A1: Product Name | B1: Cost Per Unit (UGX)
A2: Kavera 15g | B2: 330
A3: Kavera 25g | B3: 470
A4: Kavera 40g | B4: 660
A5: Baby Tin 18g | B5: 1070
A6: Baby Tin 20g | B6: 1070
A7: Masala 50g | B7: 3383.3333
A8: Black Pack 100g | B8: 3733.3333
A9: MiDAY Combo | B9: 8583.33
A10: Quail Eggs 18s | B10: 5000
A11: Roasted Coffee Beans (Kg) | B11: 12700

Sheet MASTER_SALES
A1: Date | B1: Product ID | C1: Product Name | D1: Category | E1: Quantity | F1: Unit Price | G1: Revenue | H1: Payment Status | I1: Agent | J1: Customer | K1: Customer ID | L1: Payment Method | M1: Notes | N1: COGS
A2: =IFERROR(__xludf.DUMMYFUNCTION("IFERROR(FILTER('📊 SALES'!A2:M1000, '📊 SALES'!A2:A1000 <> """"), ""⚠️ No sales data yet. Add sales in the 📊 SALES sheet."")"),46184.0) -> 46184 | B2: =IFERROR(__xludf.DUMMYFUNCTION("""COMPUTED_VALUE"""),"P003") -> P003 | C2: =IFERROR(__xludf.DUMMYFUNCTION("""COMPUTED_VALUE"""),"Kavera 40g") -> Kavera 40g | D2: =IFERROR(__xludf.DUMMYFUNCTION("""COMPUTED_VALUE"""),"Kavera") -> Kavera | E2: =IFERROR(__xludf.DUMMYFUNCTION("""COMPUTED_VALUE"""),126.0) -> 126 | F2: =IFERROR(__xludf.DUMMYFUNCTION("""COMPUTED_VALUE"""),1000.0) -> 1000 | G2: =IFERROR(__xludf.DUMMYFUNCTION("""COMPUTED_VALUE"""),126000.0) -> 126000 | H2: =IFERROR(__xludf.DUMMYFUNCTION("""COMPUTED_VALUE"""),"Paid") -> Paid | L2: =IFERROR(__xludf.DUMMYFUNCTION("""COMPUTED_VALUE"""),"Cash") -> Cash | N2: {=IFERROR(E2 * INDEX('📊 COGS'!B:B, O2), 0)} -> 83160 | O2: =MATCH(TRIM(C2), '📊 COGS'!A:A, 0) -> 4
A3: =IFERROR(__xludf.DUMMYFUNCTION("""COMPUTED_VALUE"""),46184.0) -> 46184 | B3: =IFERROR(__xludf.DUMMYFUNCTION("""COMPUTED_VALUE"""),"P004") -> P004 | C3: =IFERROR(__xludf.DUMMYFUNCTION("""COMPUTED_VALUE"""),"Baby Tin 18g") -> Baby Tin 18g | D3: =IFERROR(__xludf.DUMMYFUNCTION("""COMPUTED_VALUE"""),"Baby Tin") -> Baby Tin | E3: =IFERROR(__xludf.DUMMYFUNCTION("""COMPUTED_VALUE"""),18.0) -> 18 | F3: =IFERROR(__xludf.DUMMYFUNCTION("""COMPUTED_VALUE"""),2000.0) -> 2000 | G3: =IFERROR(__xludf.DUMMYFUNCTION("""COMPUTED_VALUE"""),36000.0) -> 36000 | H3: =IFERROR(__xludf.DUMMYFUNCTION("""COMPUTED_VALUE"""),"Paid") -> Paid | L3: =IFERROR(__xludf.DUMMYFUNCTION("""COMPUTED_VALUE"""),"Cash") -> Cash | N3: {=IFERROR(E3 * INDEX('📊 COGS'!B:B, O3), 0)} -> 19260 | O3: =MATCH(TRIM(C3), '📊 COGS'!A:A, 0) -> 5
A4: =IFERROR(__xludf.DUMMYFUNCTION("""COMPUTED_VALUE"""),46185.0) -> 46185 | B4: =IFERROR(__xludf.DUMMYFUNCTION("""COMPUTED_VALUE"""),"P007") -> P007 | C4: =IFERROR(__xludf.DUMMYFUNCTION("""COMPUTED_VALUE"""),"Black Pack 100g") -> Black Pack 100g | D4: =IFERROR(__xludf.DUMMYFUNCTION("""COMPUTED_VALUE"""),"Black Pack Small") -> Black Pack Small | E4: =IFERROR(__xludf.DUMMYFUNCTION("""COMPUTED_VALUE"""),18.0) -> 18 | F4: =IFERROR(__xludf.DUMMYFUNCTION("""COMPUTED_VALUE"""),10000.0) -> 10000 | G4: =IFERROR(__xludf.DUMMYFUNCTION("""COMPUTED_VALUE"""),180000.0) -> 180000 | H4: =IFERROR(__xludf.DUMMYFUNCTION("""COMPUTED_VALUE"""),"Paid") -> Paid | L4: =IFERROR(__xludf.DUMMYFUNCTION("""COMPUTED_VALUE"""),"Cash") -> Cash | N4: {=IFERROR(E4 * INDEX('📊 COGS'!B:B, O4), 0)} -> 67200 | O4: =MATCH(TRIM(C4), '📊 COGS'!A:A, 0) -> 8
A5: =IFERROR(__xludf.DUMMYFUNCTION("""COMPUTED_VALUE"""),46185.0) -> 46185 | B5: =IFERROR(__xludf.DUMMYFUNCTION("""COMPUTED_VALUE"""),"P001") -> P001 | C5: =IFERROR(__xludf.DUMMYFUNCTION("""COMPUTED_VALUE"""),"Kavera 15g") -> Kavera 15g | D5: =IFERROR(__xludf.DUMMYFUNCTION("""COMPUTED_VALUE"""),"Kavera") -> Kavera | E5: =IFERROR(__xludf.DUMMYFUNCTION("""COMPUTED_VALUE"""),15.0) -> 15 | F5: =IFERROR(__xludf.DUMMYFUNCTION("""COMPUTED_VALUE"""),500.0) -> 500 | G5: =IFERROR(__xludf.DUMMYFUNCTION("""COMPUTED_VALUE"""),7500.0) -> 7500 | H5: =IFERROR(__xludf.DUMMYFUNCTION("""COMPUTED_VALUE"""),"Paid") -> Paid | L5: =IFERROR(__xludf.DUMMYFUNCTION("""COMPUTED_VALUE"""),"Cash") -> Cash | N5: {=IFERROR(E5 * INDEX('📊 COGS'!B:B, O5), 0)} -> 4950 | O5: =MATCH(TRIM(C5), '📊 COGS'!A:A, 0) -> 2
A6: =IFERROR(__xludf.DUMMYFUNCTION("""COMPUTED_VALUE"""),46185.0) -> 46185 | B6: =IFERROR(__xludf.DUMMYFUNCTION("""COMPUTED_VALUE"""),"P007") -> P007 | C6: =IFERROR(__xludf.DUMMYFUNCTION("""COMPUTED_VALUE"""),"Black Pack 100g") -> Black Pack 100g | D6: =IFERROR(__xludf.DUMMYFUNCTION("""COMPUTED_VALUE"""),"Black Pack Small") -> Black Pack Small | E6: =IFERROR(__xludf.DUMMYFUNCTION("""COMPUTED_VALUE"""),6.0) -> 6 | F6: =IFERROR(__xludf.DUMMYFUNCTION("""COMPUTED_VALUE"""),10000.0) -> 10000 | G6: =IFERROR(__xludf.DUMMYFUNCTION("""COMPUTED_VALUE"""),60000.0) -> 60000 | H6: =IFERROR(__xludf.DUMMYFUNCTION("""COMPUTED_VALUE"""),"Paid") -> Paid | L6: =IFERROR(__xludf.DUMMYFUNCTION("""COMPUTED_VALUE"""),"Cash") -> Cash | N6: {=IFERROR(E6 * INDEX('📊 COGS'!B:B, O6), 0)} -> 22400 | O6: =MATCH(TRIM(C6), '📊 COGS'!A:A, 0) -> 8
A7: =IFERROR(__xludf.DUMMYFUNCTION("""COMPUTED_VALUE"""),46205.0) -> 46205 | B7: =IFERROR(__xludf.DUMMYFUNCTION("""COMPUTED_VALUE"""),"P002") -> P002 | C7: =IFERROR(__xludf.DUMMYFUNCTION("""COMPUTED_VALUE"""),"Kavera 25g") -> Kavera 25g | D7: =IFERROR(__xludf.DUMMYFUNCTION("""COMPUTED_VALUE"""),"Kavera") -> Kavera | E7: =IFERROR(__xludf.DUMMYFUNCTION("""COMPUTED_VALUE"""),160.0) -> 160 | F7: =IFERROR(__xludf.DUMMYFUNCTION("""COMPUTED_VALUE"""),1000.0) -> 1000 | G7: =IFERROR(__xludf.DUMMYFUNCTION("""COMPUTED_VALUE"""),160000.0) -> 160000 | H7: =IFERROR(__xludf.DUMMYFUNCTION("""COMPUTED_VALUE"""),"Paid") -> Paid | L7: =IFERROR(__xludf.DUMMYFUNCTION("""COMPUTED_VALUE"""),"Cash") -> Cash | N7: {=IFERROR(E7 * INDEX('📊 COGS'!B:B, O7), 0)} -> 75200 | O7: =MATCH(TRIM(C7), '📊 COGS'!A:A, 0) -> 3
A8: =IFERROR(__xludf.DUMMYFUNCTION("""COMPUTED_VALUE"""),46207.0) -> 46207 | B8: =IFERROR(__xludf.DUMMYFUNCTION("""COMPUTED_VALUE"""),"P007") -> P007 | C8: =IFERROR(__xludf.DUMMYFUNCTION("""COMPUTED_VALUE"""),"Black Pack 100g") -> Black Pack 100g | D8: =IFERROR(__xludf.DUMMYFUNCTION("""COMPUTED_VALUE"""),"Black Pack Small") -> Black Pack Small | E8: =IFERROR(__xludf.DUMMYFUNCTION("""COMPUTED_VALUE"""),1.0) -> 1 | F8: =IFERROR(__xludf.DUMMYFUNCTION("""COMPUTED_VALUE"""),10000.0) -> 10000 | G8: =IFERROR(__xludf.DUMMYFUNCTION("""COMPUTED_VALUE"""),10000.0) -> 10000 | H8: =IFERROR(__xludf.DUMMYFUNCTION("""COMPUTED_VALUE"""),"Paid") -> Paid | L8: =IFERROR(__xludf.DUMMYFUNCTION("""COMPUTED_VALUE"""),"Cash") -> Cash | N8: {=IFERROR(E8 * INDEX('📊 COGS'!B:B, O8), 0)} -> 3733.3333 | O8: =MATCH(TRIM(C8), '📊 COGS'!A:A, 0) -> 8
A9: =IFERROR(__xludf.DUMMYFUNCTION("""COMPUTED_VALUE"""),46207.0) -> 46207 | B9: =IFERROR(__xludf.DUMMYFUNCTION("""COMPUTED_VALUE"""),"P004") -> P004 | C9: =IFERROR(__xludf.DUMMYFUNCTION("""COMPUTED_VALUE"""),"Baby Tin 18g") -> Baby Tin 18g | D9: =IFERROR(__xludf.DUMMYFUNCTION("""COMPUTED_VALUE"""),"Baby Tin") -> Baby Tin | E9: =IFERROR(__xludf.DUMMYFUNCTION("""COMPUTED_VALUE"""),167.0) -> 167 | F9: =IFERROR(__xludf.DUMMYFUNCTION("""COMPUTED_VALUE"""),2000.0) -> 2000 | G9: =IFERROR(__xludf.DUMMYFUNCTION("""COMPUTED_VALUE"""),334000.0) -> 334000 | H9: =IFERROR(__xludf.DUMMYFUNCTION("""COMPUTED_VALUE"""),"Paid") -> Paid | L9: =IFERROR(__xludf.DUMMYFUNCTION("""COMPUTED_VALUE"""),"Cash") -> Cash | N9: {=IFERROR(E9 * INDEX('📊 COGS'!B:B, O9), 0)} -> 178690 | O9: =MATCH(TRIM(C9), '📊 COGS'!A:A, 0) -> 5
A10: =IFERROR(__xludf.DUMMYFUNCTION("""COMPUTED_VALUE"""),46235.0) -> 46235 | B10: =IFERROR(__xludf.DUMMYFUNCTION("""COMPUTED_VALUE"""),"P009") -> P009 | C10: =IFERROR(__xludf.DUMMYFUNCTION("""COMPUTED_VALUE"""),"Quail Eggs 18s") -> Quail Eggs 18s | D10: =IFERROR(__xludf.DUMMYFUNCTION("""COMPUTED_VALUE"""),"Eggs") -> Eggs | E10: =IFERROR(__xludf.DUMMYFUNCTION("""COMPUTED_VALUE"""),8.0) -> 8 | F10: =IFERROR(__xludf.DUMMYFUNCTION("""COMPUTED_VALUE"""),8000.0) -> 8000 | G10: =IFERROR(__xludf.DUMMYFUNCTION("""COMPUTED_VALUE"""),64000.0) -> 64000 | H10: =IFERROR(__xludf.DUMMYFUNCTION("""COMPUTED_VALUE"""),"Partial") -> Partial | L10: =IFERROR(__xludf.DUMMYFUNCTION("""COMPUTED_VALUE"""),"Cash") -> Cash | M10: =IFERROR(__xludf.DUMMYFUNCTION("""COMPUTED_VALUE"""),"2trays in debt") -> 2trays in debt | N10: {=IFERROR(E10 * INDEX('📊 COGS'!B:B, O10), 0)} -> 40000 | O10: =MATCH(TRIM(C10), '📊 COGS'!A:A, 0) -> 10
A11: =IFERROR(__xludf.DUMMYFUNCTION("""COMPUTED_VALUE"""),46235.0) -> 46235 | B11: =IFERROR(__xludf.DUMMYFUNCTION("""COMPUTED_VALUE"""),"P006") -> P006 | C11: =IFERROR(__xludf.DUMMYFUNCTION("""COMPUTED_VALUE"""),"Spiced 50g") -> Spiced 50g | D11: =IFERROR(__xludf.DUMMYFUNCTION("""COMPUTED_VALUE"""),"Spiced") -> Spiced | E11: =IFERROR(__xludf.DUMMYFUNCTION("""COMPUTED_VALUE"""),8.0) -> 8 | F11: =IFERROR(__xludf.DUMMYFUNCTION("""COMPUTED_VALUE"""),5000.0) -> 5000 | G11: =IFERROR(__xludf.DUMMYFUNCTION("""COMPUTED_VALUE"""),40000.0) -> 40000 | H11: =IFERROR(__xludf.DUMMYFUNCTION("""COMPUTED_VALUE"""),"Paid") -> Paid | L11: =IFERROR(__xludf.DUMMYFUNCTION("""COMPUTED_VALUE"""),"Cash") -> Cash | N11: {=IFERROR(E11 * INDEX('📊 COGS'!B:B, O11), 0)} -> 0 | O11: =MATCH(TRIM(C11), '📊 COGS'!A:A, 0) -> #N/A
A12: =IFERROR(__xludf.DUMMYFUNCTION("""COMPUTED_VALUE"""),46235.0) -> 46235 | B12: =IFERROR(__xludf.DUMMYFUNCTION("""COMPUTED_VALUE"""),"P007") -> P007 | C12: =IFERROR(__xludf.DUMMYFUNCTION("""COMPUTED_VALUE"""),"Black Pack 100g") -> Black Pack 100g | D12: =IFERROR(__xludf.DUMMYFUNCTION("""COMPUTED_VALUE"""),"Black Pack Small") -> Black Pack Small | E12: =IFERROR(__xludf.DUMMYFUNCTION("""COMPUTED_VALUE"""),6.0) -> 6 | F12: =IFERROR(__xludf.DUMMYFUNCTION("""COMPUTED_VALUE"""),10000.0) -> 10000 | G12: =IFERROR(__xludf.DUMMYFUNCTION("""COMPUTED_VALUE"""),60000.0) -> 60000 | H12: =IFERROR(__xludf.DUMMYFUNCTION("""COMPUTED_VALUE"""),"Paid") -> Paid | L12: =IFERROR(__xludf.DUMMYFUNCTION("""COMPUTED_VALUE"""),"Cash") -> Cash | N12: {=IFERROR(E12 * INDEX('📊 COGS'!B:B, O12), 0)} -> 22400 | O12: =MATCH(TRIM(C12), '📊 COGS'!A:A, 0) -> 8
A13: =IFERROR(__xludf.DUMMYFUNCTION("""COMPUTED_VALUE"""),46235.0) -> 46235 | B13: =IFERROR(__xludf.DUMMYFUNCTION("""COMPUTED_VALUE"""),"P004") -> P004 | C13: =IFERROR(__xludf.DUMMYFUNCTION("""COMPUTED_VALUE"""),"Baby Tin 18g") -> Baby Tin 18g | D13: =IFERROR(__xludf.DUMMYFUNCTION("""COMPUTED_VALUE"""),"Baby Tin") -> Baby Tin | E13: =IFERROR(__xludf.DUMMYFUNCTION("""COMPUTED_VALUE"""),5.0) -> 5 | F13: =IFERROR(__xludf.DUMMYFUNCTION("""COMPUTED_VALUE"""),2000.0) -> 2000 | G13: =IFERROR(__xludf.DUMMYFUNCTION("""COMPUTED_VALUE"""),10000.0) -> 10000 | H13: =IFERROR(__xludf.DUMMYFUNCTION("""COMPUTED_VALUE"""),"Paid") -> Paid | L13: =IFERROR(__xludf.DUMMYFUNCTION("""COMPUTED_VALUE"""),"Cash") -> Cash | N13: {=IFERROR(E13 * INDEX('📊 COGS'!B:B, O13), 0)} -> 5350 | O13: =MATCH(TRIM(C13), '📊 COGS'!A:A, 0) -> 5
A14: =IFERROR(__xludf.DUMMYFUNCTION("""COMPUTED_VALUE"""),46240.0) -> 46240 | B14: =IFERROR(__xludf.DUMMYFUNCTION("""COMPUTED_VALUE"""),"P006") -> P006 | C14: =IFERROR(__xludf.DUMMYFUNCTION("""COMPUTED_VALUE"""),"Spiced 50g") -> Spiced 50g | D14: =IFERROR(__xludf.DUMMYFUNCTION("""COMPUTED_VALUE"""),"Spiced") -> Spiced | E14: =IFERROR(__xludf.DUMMYFUNCTION("""COMPUTED_VALUE"""),9.0) -> 9 | F14: =IFERROR(__xludf.DUMMYFUNCTION("""COMPUTED_VALUE"""),5000.0) -> 5000 | G14: =IFERROR(__xludf.DUMMYFUNCTION("""COMPUTED_VALUE"""),45000.0) -> 45000 | H14: =IFERROR(__xludf.DUMMYFUNCTION("""COMPUTED_VALUE"""),"Paid") -> Paid | L14: =IFERROR(__xludf.DUMMYFUNCTION("""COMPUTED_VALUE"""),"Cash") -> Cash | N14: {=IFERROR(E14 * INDEX('📊 COGS'!B:B, O14), 0)} -> 0 | O14: =MATCH(TRIM(C14), '📊 COGS'!A:A, 0) -> #N/A
A15: =IFERROR(__xludf.DUMMYFUNCTION("""COMPUTED_VALUE"""),46240.0) -> 46240 | B15: =IFERROR(__xludf.DUMMYFUNCTION("""COMPUTED_VALUE"""),"P009") -> P009 | C15: =IFERROR(__xludf.DUMMYFUNCTION("""COMPUTED_VALUE"""),"Quail Eggs 18s") -> Quail Eggs 18s | D15: =IFERROR(__xludf.DUMMYFUNCTION("""COMPUTED_VALUE"""),"Eggs") -> Eggs | E15: =IFERROR(__xludf.DUMMYFUNCTION("""COMPUTED_VALUE"""),2.0) -> 2 | F15: =IFERROR(__xludf.DUMMYFUNCTION("""COMPUTED_VALUE"""),8000.0) -> 8000 | G15: =IFERROR(__xludf.DUMMYFUNCTION("""COMPUTED_VALUE"""),16000.0) -> 16000 | H15: =IFERROR(__xludf.DUMMYFUNCTION("""COMPUTED_VALUE"""),"Paid") -> Paid | L15: =IFERROR(__xludf.DUMMYFUNCTION("""COMPUTED_VALUE"""),"Cash") -> Cash | N15: {=IFERROR(E15 * INDEX('📊 COGS'!B:B, O15), 0)} -> 10000 | O15: =MATCH(TRIM(C15), '📊 COGS'!A:A, 0) -> 10
A16: =IFERROR(__xludf.DUMMYFUNCTION("""COMPUTED_VALUE"""),46240.0) -> 46240 | B16: =IFERROR(__xludf.DUMMYFUNCTION("""COMPUTED_VALUE"""),"P004") -> P004 | C16: =IFERROR(__xludf.DUMMYFUNCTION("""COMPUTED_VALUE"""),"Baby Tin 18g") -> Baby Tin 18g | D16: =IFERROR(__xludf.DUMMYFUNCTION("""COMPUTED_VALUE"""),"Baby Tin") -> Baby Tin | E16: =IFERROR(__xludf.DUMMYFUNCTION("""COMPUTED_VALUE"""),7.0) -> 7 | F16: =IFERROR(__xludf.DUMMYFUNCTION("""COMPUTED_VALUE"""),2000.0) -> 2000 | G16: =IFERROR(__xludf.DUMMYFUNCTION("""COMPUTED_VALUE"""),14000.0) -> 14000 | H16: =IFERROR(__xludf.DUMMYFUNCTION("""COMPUTED_VALUE"""),"Paid") -> Paid | L16: =IFERROR(__xludf.DUMMYFUNCTION("""COMPUTED_VALUE"""),"Cash") -> Cash | N16: {=IFERROR(E16 * INDEX('📊 COGS'!B:B, O16), 0)} -> 7490 | O16: =MATCH(TRIM(C16), '📊 COGS'!A:A, 0) -> 5
A17: =IFERROR(__xludf.DUMMYFUNCTION("""COMPUTED_VALUE"""),46242.0) -> 46242 | B17: =IFERROR(__xludf.DUMMYFUNCTION("""COMPUTED_VALUE"""),"P006") -> P006 | C17: =IFERROR(__xludf.DUMMYFUNCTION("""COMPUTED_VALUE"""),"Spiced 50g") -> Spiced 50g | D17: =IFERROR(__xludf.DUMMYFUNCTION("""COMPUTED_VALUE"""),"Spiced") -> Spiced | E17: =IFERROR(__xludf.DUMMYFUNCTION("""COMPUTED_VALUE"""),3.0) -> 3 | F17: =IFERROR(__xludf.DUMMYFUNCTION("""COMPUTED_VALUE"""),5000.0) -> 5000 | G17: =IFERROR(__xludf.DUMMYFUNCTION("""COMPUTED_VALUE"""),15000.0) -> 15000 | H17: =IFERROR(__xludf.DUMMYFUNCTION("""COMPUTED_VALUE"""),"Paid") -> Paid | L17: =IFERROR(__xludf.DUMMYFUNCTION("""COMPUTED_VALUE"""),"Cash") -> Cash | N17: {=IFERROR(E17 * INDEX('📊 COGS'!B:B, O17), 0)} -> 0 | O17: =MATCH(TRIM(C17), '📊 COGS'!A:A, 0) -> #N/A
A18: =IFERROR(__xludf.DUMMYFUNCTION("""COMPUTED_VALUE"""),46244.0) -> 46244 | B18: =IFERROR(__xludf.DUMMYFUNCTION("""COMPUTED_VALUE"""),"P006") -> P006 | C18: =IFERROR(__xludf.DUMMYFUNCTION("""COMPUTED_VALUE"""),"Spiced 50g") -> Spiced 50g | D18: =IFERROR(__xludf.DUMMYFUNCTION("""COMPUTED_VALUE"""),"Spiced") -> Spiced | E18: =IFERROR(__xludf.DUMMYFUNCTION("""COMPUTED_VALUE"""),4.0) -> 4 | F18: =IFERROR(__xludf.DUMMYFUNCTION("""COMPUTED_VALUE"""),5000.0) -> 5000 | G18: =IFERROR(__xludf.DUMMYFUNCTION("""COMPUTED_VALUE"""),20000.0) -> 20000 | H18: =IFERROR(__xludf.DUMMYFUNCTION("""COMPUTED_VALUE"""),"Paid") -> Paid | L18: =IFERROR(__xludf.DUMMYFUNCTION("""COMPUTED_VALUE"""),"Cash") -> Cash | N18: {=IFERROR(E18 * INDEX('📊 COGS'!B:B, O18), 0)} -> 0 | O18: =MATCH(TRIM(C18), '📊 COGS'!A:A, 0) -> #N/A
A19: =IFERROR(__xludf.DUMMYFUNCTION("""COMPUTED_VALUE"""),46244.0) -> 46244 | B19: =IFERROR(__xludf.DUMMYFUNCTION("""COMPUTED_VALUE"""),"P004") -> P004 | C19: =IFERROR(__xludf.DUMMYFUNCTION("""COMPUTED_VALUE"""),"Baby Tin 18g") -> Baby Tin 18g | D19: =IFERROR(__xludf.DUMMYFUNCTION("""COMPUTED_VALUE"""),"Baby Tin") -> Baby Tin | E19: =IFERROR(__xludf.DUMMYFUNCTION("""COMPUTED_VALUE"""),2.0) -> 2 | F19: =IFERROR(__xludf.DUMMYFUNCTION("""COMPUTED_VALUE"""),2000.0) -> 2000 | G19: =IFERROR(__xludf.DUMMYFUNCTION("""COMPUTED_VALUE"""),4000.0) -> 4000 | H19: =IFERROR(__xludf.DUMMYFUNCTION("""COMPUTED_VALUE"""),"Paid") -> Paid | L19: =IFERROR(__xludf.DUMMYFUNCTION("""COMPUTED_VALUE"""),"Cash") -> Cash | N19: {=IFERROR(E19 * INDEX('📊 COGS'!B:B, O19), 0)} -> 2140 | O19: =MATCH(TRIM(C19), '📊 COGS'!A:A, 0) -> 5
